<robot name="my_robot" xmlns:xacro="http://www.ros.org/wiki/xacro">
    <xacro:include filename="$(find my_robot)/urdf/my_robot.gazebo"/>
    <link name="robot_footprint"/>
    <joint name="robot_footprint_joint" type="fixed">
        <origin xyz="0 0 0" rpy="0 0 0"/>
        <parent link="robot_footprint"/>
        <child link="chassis"/>
    </joint>
    <link name='chassis'>
        <pose>0 0 0.3 0 0 0</pose>

        <inertial>
            <mass value="15.0"/>
            <origin xyz="0.0 0 0" rpy=" 0 0 0"/>
            <inertia
                ixx="0.1" ixy="0" ixz="0"
                iyy="0.1" iyz="0"
                izz="0.1"
            />
        </inertial>

        <collision name='collision'>
            <origin xyz="0 0 0" rpy=" 0 0 0"/> 
            <geometry>
                <box size="1.0 .7 .3"/>
            </geometry>
        </collision>

        <visual name='chassis_visual'>
        <origin xyz="0 0 0" rpy=" 0 0 0"/>
            <geometry>
                <box size="1.0 .7 .3"/>
            </geometry>
        </visual>


        <collision name='back_right_caster_collision'>
            <origin xyz="-0.4 -0.2 -0.15" rpy=" 0 0 0"/>
            <geometry>
                <sphere radius="0.1"/>
            </geometry>
        </collision>

        <visual name='back_right_caster_visual'>
            <origin xyz="-0.4 -0.2 -0.15" rpy=" 0 0 0"/>
            <geometry>
                <sphere radius="0.1"/>
            </geometry>
        </visual>

        <collision name='front_right_caster_collision'>
            <origin xyz="0.4 -0.2 -0.15" rpy=" 0 0 0"/>
            <geometry>
                <sphere radius="0.1"/>
            </geometry>
        </collision>

        <visual name='front_right_caster_visual'>
            <origin xyz="0.4 -0.2 -0.15" rpy=" 0 0 0"/>
            <geometry>
                <sphere radius="0.1"/>
            </geometry>
        </visual>

        <collision name='back_left_caster_collision'>
            <origin xyz="-0.4 0.2 -0.15" rpy=" 0 0 0"/>
            <geometry>
                <sphere radius="0.1"/>
            </geometry>
        </collision>

        <visual name='back_left_caster_visual'>
            <origin xyz="-0.4 0.2 -0.15" rpy=" 0 0 0"/>
            <geometry>
                <sphere radius="0.1"/>
            </geometry>
        </visual>

        <collision name='front_left_caster_collision'>
            <origin xyz="0.4 0.2 -0.15" rpy=" 0 0 0"/>
            <geometry>
                <sphere radius="0.1"/>
            </geometry>
        </collision>

        <visual name='front_left_caster_visual'>
            <origin xyz="0.4 0.2 -0.15" rpy=" 0 0 0"/>
            <geometry>
                <sphere radius="0.1"/>
            </geometry>
        </visual>
  </link>

  <link name="right_wheel">
    <visual name='right_wheel_visual'>
      <origin xyz="0 0 0 " rpy="0 1.57 1.57"/>
      <geometry>
        <cylinder length="0.05" radius="0.2"/>
      </geometry>
    </visual>

    <collision name="right_wheel_collsion">
      <origin xyz="0 0 0 " rpy="0 1.57 1.57"/>
      <geometry>
        <cylinder length="0.05" radius="0.2"/>
      </geometry>
    </collision>

    <inertial> 
      <mass value="5"/>
      <inertia
           ixx="0.1" ixy="0" ixz="0"
           iyy="0.1" iyz="0"
           izz="0.1"
      />
    </inertial>
  </link>
  <link name="left_wheel">
    <visual name='left_wheel_visual'>
      <origin xyz="0 0 0 " rpy="0 1.57 1.57"/>
      <geometry>
        <cylinder length="0.05" radius="0.2"/>
      </geometry>
    </visual>

    <collision name="left_wheel_collsion">
      <origin xyz="0 0 0 " rpy="0 1.57 1.57"/>
      <geometry>
        <cylinder length="0.05" radius="0.2"/>
      </geometry>
    </collision>

    <inertial> 
      <mass value="5"/>
      <inertia
           ixx="0.1" ixy="0" ixz="0"
           iyy="0.1" iyz="0"
           izz="0.1"
      />
    </inertial>
  </link>

  <link name="camera">
    <visual name="camera_visual">
      <origin xyz="0 0 0 " rpy="0 0 0"/>
      <geometry>
        <box size=".05 .05 .05"/>
      </geometry>
    </visual>

    <collision name="camera_collsion">
      <origin xyz="0 0 0 " rpy="0 0 0"/>
      <geometry>
        <box size=".05 .05 .05"/>
      </geometry>
    </collision>

    <inertial>
      <origin xyz="0 0 0 " rpy="0 0 0"/>
      <mass value="0.1"/>
      <box_inertia m="0.1" x=".05" y=".05" z=".05"/>
      <inertia
           ixx="1e-6" ixy="0" ixz="0"
           iyy="1e-6" iyz="0"
           izz="1e-6"
      />
    </inertial>
  </link>

  <link name="hokuyo">
    <visual name="hokuyo_visual">
      <origin xyz="0 0 0 " rpy="0 0 0"/>
      <geometry>
          <mesh filename="package://my_robot/meshes/hokuyo.dae"/>
      </geometry>
    </visual>

    <collision name="hokuyo_collsion">
      <origin xyz="0 0 0 " rpy="0 0 0"/>
      <geometry>
        <box size=".1 .1 .1"/>
      </geometry>
    </collision>

    <inertial>
      <origin xyz="0 0 0 " rpy="0 0 0"/>
      <mass value="1e-5"/>
      <inertia
           ixx="1e-6" ixy="0" ixz="0"
           iyy="1e-6" iyz="0"
           izz="1e-6"
      />
    </inertial>
  </link>

  <joint name="hokuyo_joint" type="fixed">
    <origin xyz="0.45 0 0.15" rpy="0 0 0"/>
    <child link="hokuyo"/>
    <parent link="chassis"/>
    <axis xyz="0 1 0"/>
  </joint>


  <joint name="camera_joint" type="fixed">
    <origin xyz="0.5 0 0" rpy="0 0 0"/>
    <child link="camera"/>
    <parent link="chassis"/>
    <axis xyz="0 1 0"/>
  </joint>

  <joint type="continuous" name="right_wheel_hinge">
    <origin xyz="0 -0.3 -0.05" rpy="0 0 0"/>
    <child link="right_wheel"/>
    <parent link="chassis"/>
    <axis xyz="0 1 0" rpy="0 0 0"/>
    <limit effort="10000" velocity="1000"/>
    <dynamics damping="1.0" friction="1.0"/>
  </joint>

  <joint type="continuous" name="left_wheel_hinge">
    <origin xyz="0 0.3 -0.05" rpy="0 0 0"/>
    <child link="left_wheel"/>
    <parent link="chassis"/>
    <axis xyz="0 1 0" rpy="0 0 0"/>
    <limit effort="10000" velocity="1000"/>
    <dynamics damping="1.0" friction="1.0"/>
  </joint>

  <gazebo reference="left_wheel">
    <material>Gazebo/BlueGlow</material>
  </gazebo>

  <gazebo reference="right_wheel">
    <material>Gazebo/BlueGlow</material>
  </gazebo>

  <gazebo reference="chassis">
    <material>Gazebo/DarkGrey</material>
  </gazebo>

  <gazebo reference="camera">
    <material>Gazebo/Yellow</material>
  </gazebo>


</robot>
